<?xml version="1.0" ?>
<!-- =================================================================================== -->
<!-- |    This document was autogenerated by xacro from drawer_one_sided_handle.xacro  | -->
<!-- |    EDITING THIS FILE BY HAND IS NOT RECOMMENDED                                 | -->
<!-- =================================================================================== -->
<robot name="drawer" xmlns:xacro="http://ros.org/wiki/xacro">
  <material name="omni/Blue">
    <color rgba="0 0 0.8 1"/>
  </material>
  <material name="omni/Red">
    <color rgba="1 0 0 1"/>
  </material>
  <material name="omni/White">
    <color rgba="1 1 1 1"/>
  </material>
  <material name="omni/Green">
    <color rgba="0 1 0 1"/>
  </material>
  <material name="omni/Yellow">
    <color rgba="1 1 0 1"/>
  </material>
  <material name="omni/LightGrey">
    <color rgba="0.6 0.6 0.6 1"/>
  </material>
  <material name="omni/DarkGrey">
    <color rgba="0.4 0.4 0.4 1"/>
  </material>
  <link name="base_link">    
    </link>
  <link name="drawer">
    <visual>
      <origin rpy="0 0 0" xyz="0 0 0"/>
      <geometry>
        <box size="1.0 0.6 0.3"/>
      </geometry>
      <material name="omni/LightGrey"/>
    </visual>
    <collision>
      <origin rpy="0 0 0" xyz="0 0 0"/>
      <geometry>
        <box size="1.0 0.6 0.3"/>
      </geometry>
      <contact_coefficients mu="0.0"/>
    </collision>
    <inertial>
      <!-- CENTER OF MASS -->
      <origin rpy="0 0 0" xyz="0 0 0"/>
      <mass value="0.1"/>
      <!-- box inertia: 1/12*m(y^2+z^2), ... -->
      <inertia ixx="0.0225" ixy="0" ixz="0" iyy="0.0545" iyz="0" izz="0.068"/>
    </inertial>
  </link>
  <joint name="base_drawer_joint" type="prismatic">
    <origin rpy="0 0 0" xyz="0 0 0"/>
    <parent link="base_link"/>
    <child link="drawer"/>
    <dynamics damping="1.0" friction="1.0"/>
    <limit effort="0.1" lower="0.0" upper="0.5" velocity="10.0"/>
    <axis xyz="1 0 0"/>
  </joint>
  <link name="left_wall">
    <visual>
      <origin rpy="0 0 0" xyz="0 0 0"/>
      <geometry>
        <box size="1.01 0.02 0.32"/>
      </geometry>
      <material name="omni/White"/>
    </visual>
    <collision>
      <origin rpy="0 0 0" xyz="0 0 0.0"/>
      <geometry>
        <box size="1.01 0.02 0.32"/>
      </geometry>
    </collision>
    <inertial>
      <!-- CENTER OF MASS -->
      <origin rpy="0 0 0" xyz="0 0 0"/>
      <mass value="0.05"/>
      <!-- box inertia: 1/12*m(y^2+z^2), ... -->
      <inertia ixx="0.00257" ixy="0" ixz="0" iyy="0.0280625" iyz="0" izz="0.0255125"/>
    </inertial>
  </link>
  <joint name="b_2_lw" type="fixed">
    <origin rpy="0 0 0" xyz="-0.01 -0.32 0"/>
    <parent link="base_link"/>
    <child link="left_wall"/>
  </joint>
  <link name="right_wall">
    <visual>
      <origin rpy="0 0 0" xyz="0 0 0"/>
      <geometry>
        <box size="1.01 0.02 0.32"/>
      </geometry>
      <material name="omni/White"/>
    </visual>
    <collision>
      <origin rpy="0 0 0" xyz="0 0 0.0"/>
      <geometry>
        <box size="1.01 0.02 0.32"/>
      </geometry>
    </collision>
    <inertial>
      <!-- CENTER OF MASS -->
      <origin rpy="0 0 0" xyz="0 0 0"/>
      <mass value="0.05"/>
      <!-- box inertia: 1/12*m(y^2+z^2), ... -->
      <inertia ixx="0.00257" ixy="0" ixz="0" iyy="0.0280625" iyz="0" izz="0.0255125"/>
    </inertial>
  </link>
  <joint name="b_2_rw" type="fixed">
    <origin rpy="0 0 0" xyz="-0.01 0.32 0"/>
    <parent link="base_link"/>
    <child link="right_wall"/>
  </joint>
  <link name="bottom_wall">
    <visual>
      <origin rpy="0 0 0" xyz="0 0 0"/>
      <geometry>
        <box size="1.01 0.66 0.02"/>
      </geometry>
      <material name="omni/White"/>
    </visual>
    <collision>
      <origin rpy="0 0 0" xyz="0 0 0.0"/>
      <geometry>
        <box size="1.01 0.66 0.02"/>
      </geometry>
    </collision>
    <inertial>
      <!-- CENTER OF MASS -->
      <origin rpy="0 0 0" xyz="0 0 0"/>
      <mass value="0.05"/>
      <!-- box inertia: 1/12*m(y^2+z^2), ... -->
      <inertia ixx="0.0109" ixy="0" ixz="0" iyy="0.0255125" iyz="0" izz="0.0363925"/>
    </inertial>
  </link>
  <joint name="b_2_bw" type="fixed">
    <origin rpy="0 0 0" xyz="-0.01 0 -0.17"/>
    <parent link="base_link"/>
    <child link="bottom_wall"/>
  </joint>
  <link name="top_wall">
    <visual>
      <origin rpy="0 0 0" xyz="0 0 0"/>
      <geometry>
        <box size="1.01 0.66 0.02"/>
      </geometry>
      <material name="omni/White"/>
    </visual>
    <collision>
      <origin rpy="0 0 0" xyz="0 0 0.0"/>
      <geometry>
        <box size="1.01 0.66 0.02"/>
      </geometry>
    </collision>
    <inertial>
      <!-- CENTER OF MASS -->
      <origin rpy="0 0 0" xyz="0 0 0"/>
      <mass value="0.05"/>
      <!-- box inertia: 1/12*m(y^2+z^2), ... -->
      <inertia ixx="0.0109" ixy="0" ixz="0" iyy="0.0255125" iyz="0" izz="0.0363925"/>
    </inertial>
  </link>
  <joint name="b_2_tw" type="fixed">
    <origin rpy="0 0 0" xyz="-0.01 0 0.17"/>
    <parent link="base_link"/>
    <child link="top_wall"/>
  </joint>
  <link name="back_wall">
    <visual>
      <origin rpy="0 0 0" xyz="0 0 0"/>
      <geometry>
        <box size="0.02 0.66 0.36"/>
      </geometry>
      <material name="omni/White"/>
    </visual>
    <collision>
      <origin rpy="0 0 0" xyz="0 0 0.0"/>
      <geometry>
        <box size="0.02 0.66 0.36"/>
      </geometry>
    </collision>
    <inertial>
      <!-- CENTER OF MASS -->
      <origin rpy="0 0 0" xyz="0 0 0"/>
      <mass value="0.05"/>
      <!-- box inertia: 1/12*m(y^2+z^2), ... -->
      <inertia ixx="0.01413" ixy="0" ixz="0" iyy="0.00325" iyz="0" izz="0.02178"/>
    </inertial>
  </link>
  <joint name="b_2_backw" type="fixed">
    <origin rpy="0 0 0" xyz="-0.52 0 0"/>
    <parent link="base_link"/>
    <child link="back_wall"/>
  </joint>
  <link name="handle_left">
    <visual>
      <origin rpy="0 0 0" xyz="0 0 0"/>
      <geometry>
        <box size="0.06 0.02 0.02"/>
      </geometry>
      <material name="omni/White"/>
    </visual>
    <collision>
      <origin rpy="0 0 0" xyz="0 0 0.0"/>
      <geometry>
        <box size="0.06 0.02 0.02"/>
      </geometry>
    </collision>
    <inertial>
      <!-- CENTER OF MASS -->
      <origin rpy="0 0 0" xyz="0 0 0"/>
      <mass value="0.05"/>
      <!-- box inertia: 1/12*m(y^2+z^2), ... -->
      <inertia ixx="2e-05" ixy="0" ixz="0" iyy="0.0001" iyz="0" izz="0.0001"/>
    </inertial>
  </link>
  <joint name="d_2_hl" type="fixed">
    <origin rpy="0 0 0" xyz="0.53 -0.085 0"/>
    <parent link="drawer"/>
    <child link="handle_left"/>
  </joint>
  <link name="handle_right">
    <visual>
      <origin rpy="0 0 0" xyz="0 0 0"/>
      <geometry>
        <box size="0.06 0.02 0.02"/>
      </geometry>
      <material name="omni/White"/>
    </visual>
    <collision>
      <origin rpy="0 0 0" xyz="0 0 0.0"/>
      <geometry>
        <box size="0.06 0.02 0.02"/>
      </geometry>
    </collision>
    <inertial>
      <!-- CENTER OF MASS -->
      <origin rpy="0 0 0" xyz="0 0 0"/>
      <mass value="0.05"/>
      <!-- box inertia: 1/12*m(y^2+z^2), ... -->
      <inertia ixx="2e-05" ixy="0" ixz="0" iyy="0.0001" iyz="0" izz="0.0001"/>
    </inertial>
  </link>
  <joint name="d_2_hr" type="fixed">
    <origin rpy="0 0 0" xyz="0.53 0.085 0"/>
    <parent link="drawer"/>
    <child link="handle_right"/>
  </joint>
  <link name="handle_grip">
    <visual>
      <origin rpy="0 0 0" xyz="0 0 0"/>
      <geometry>
        <box size="0.02 0.19 0.02"/>
      </geometry>
      <material name="omni/White"/>
    </visual>
    <collision>
      <origin rpy="0 0 0" xyz="0 0 0.0"/>
      <geometry>
        <box size="0.02 0.19 0.02"/>
      </geometry>
    </collision>
    <inertial>
      <!-- CENTER OF MASS -->
      <origin rpy="0 0 0" xyz="0 0 0"/>
      <mass value="0.05"/>
      <!-- box inertia: 1/12*m(y^2+z^2), ... -->
      <inertia ixx="0.0009125" ixy="0" ixz="0" iyy="2e-05" iyz="0" izz="0.0009125"/>
    </inertial>
  </link>
  <joint name="d_2_hg" type="fixed">
    <origin rpy="0 0 0" xyz="0.57 0 0"/>
    <parent link="drawer"/>
    <child link="handle_grip"/>
  </joint>
  <link name="handle_top_cover">
    <visual>
      <origin rpy="0 0 0" xyz="0 0 0"/>
      <geometry>
        <!-- <box size="${handle_gap + handle_thickness} ${handle_span + 2 * handle_thickness} ${handle_thickness * 20}"/> -->
        <box size="0.08 0.19 0.006"/>
      </geometry>
      <material name="omni/White"/>
    </visual>
    <collision>
      <origin rpy="0 0 0" xyz="0 0 0.0"/>
      <geometry>
        <box size="0.08 0.19 0.006"/>
      </geometry>
      <contact_coefficients mu="0.0"/>
    </collision>
    <inertial>
      <origin rpy="0 0 0" xyz="0 0 0"/>
      <mass value="0.05"/>
      <inertia ixx="0.0009125" ixy="0" ixz="0" iyy="0.0001" iyz="0" izz="0.0009925"/>
    </inertial>
  </link>
  <joint name="d_2_htc" type="fixed">
    <origin rpy="0 0 0" xyz="0.54 0 -0.043"/>
    <parent link="drawer"/>
    <child link="handle_top_cover"/>
  </joint>
  <link name="handle_bottom_cover">
    <visual>
      <origin rpy="0 0 0" xyz="0 0 0"/>
      <geometry>
        <!-- <box size="${handle_gap + handle_thickness} ${handle_span + 2 * handle_thickness} ${handle_thickness * 20}"/> -->
        <box size="0.006 0.19 0.113136"/>
      </geometry>
      <material name="omni/White"/>
    </visual>
    <collision>
      <origin rpy="0 0 0" xyz="0 0 0.0"/>
      <geometry>
        <box size="0.006 0.19 0.113136"/>
      </geometry>
      <contact_coefficients mu="0.0"/>
    </collision>
    <inertial>
      <origin rpy="0 0 0" xyz="0 0 0"/>
      <mass value="0.05"/>
      <inertia ixx="0.0009125" ixy="0" ixz="0" iyy="0.0001" iyz="0" izz="0.0009925"/>
    </inertial>
  </link>
  <joint name="d_2_hbc" type="fixed">
    <origin rpy="0 0.78539816339 0" xyz="-0.001 0 -0.04"/>
    <parent link="handle_top_cover"/>
    <child link="handle_bottom_cover"/>
  </joint>
</robot>

